Workbook

Sheet HC Total Nov 2024-2026
A1: No. | B1: NOMBRE COMPLETO | C1: Nombre corto | D1: Correo | E1: Área | F1: Puesto | G1: Cliente | H1: Proyecto 1 | I1: Evaluador 1 | J1: Evaluador 1 A | K1: Proyecto 2 | L1: Evaluador 2 | M1: Proyecto 3 | N1: Evaluador 3 | O1: Proyecto 4 | P1: Evaluador 4
A2: 1 | B2: RAMIRO ABAD ARELLANO CARDONA | C2: Abad Arellano Cardona | D2: abad.arellano@arena-analytics.com | E2: Analítica | F2: Ingeniero(a) de Datos Snr | G2: =_xlfn.XLOOKUP(H2,'Proyectos Dueños'!$B$2:$B$18,'Proyectos Dueños'!$C$2:$C$18,"") -> The Coca Cola Company | H2: CCL Engineering Cell | I2: Héctor Rangel | K2: Migración 360 a 720 | L2: =_xlfn.XLOOKUP(K2,'Proyectos Dueños'!$B$2:$B$18,'Proyectos Dueños'!$D$2:$D$18,"") -> Kareem Galvan | M2: OBPPC | N2: =_xlfn.XLOOKUP(M2,'Proyectos Dueños'!$B$2:$B$18,'Proyectos Dueños'!$D$2:$D$18,"") -> Luis Adrián Lara García | O2: Prime Partners Support
A3: 2 | B3: ABRAHAM MARTÍNEZ RAMIREZ | C3: Abraham Martínez Ramirez | D3: abraham.martinez@arena-analytics.com | E3: Analítica | F3: Ingeniero(a) de Datos Snr | G3: =_xlfn.XLOOKUP(H3,'Proyectos Dueños'!$B$2:$B$18,'Proyectos Dueños'!$C$2:$C$18,"") -> The Coca Cola Company | H3: C&CL Report | I3: José Antonio Pedraza | L3: =_xlfn.XLOOKUP(K3,'Proyectos Dueños'!$B$2:$B$18,'Proyectos Dueños'!$D$2:$D$18,"") | M3: OBPPC | N3: =_xlfn.XLOOKUP(M3,'Proyectos Dueños'!$B$2:$B$18,'Proyectos Dueños'!$D$2:$D$18,"") -> Luis Adrián Lara García | O3: Share Forecast LATAM / Apollo 2.0
A4: 3 | B4: ADRIÁN LANDAVERDE NAVA | C4: Adrián Landaverde Nava | D4: adrian@arena-analytics.com | E4: Analítica | F4: Científico(a) de Datos Mid | G4: =_xlfn.XLOOKUP(H4,'Proyectos Dueños'!$B$2:$B$18,'Proyectos Dueños'!$C$2:$C$18,"") -> The Coca Cola Company | H4: GenAI | I4: Marco Aristeo | K4: Weather | L4: =_xlfn.XLOOKUP(K4,'Proyectos Dueños'!$B$2:$B$18,'Proyectos Dueños'!$D$2:$D$18,"") -> Eduardo Ayala | N4: =_xlfn.XLOOKUP(M4,'Proyectos Dueños'!$B$2:$B$18,'Proyectos Dueños'!$D$2:$D$18,"")
A5: 4 | B5: ADRIÁN PÉREZ ÁNGELES | C5: Adrián Pérez Ángeles | D5: adrian.perez@arena-analytics.com | E5: Analítica | F5: Científico(a) de Datos Jr | G5: =_xlfn.XLOOKUP(H5,'Proyectos Dueños'!$B$2:$B$18,'Proyectos Dueños'!$C$2:$C$18,"") -> The Coca Cola Company | H5: Share Forecast LATAM / Apollo 2.0 | I5: Oscar Mancha | L5: =_xlfn.XLOOKUP(K5,'Proyectos Dueños'!$B$2:$B$18,'Proyectos Dueños'!$D$2:$D$18,"") | N5: =_xlfn.XLOOKUP(M5,'Proyectos Dueños'!$B$2:$B$18,'Proyectos Dueños'!$D$2:$D$18,"")
A6: 5 | B6: ALDO ALEJANDRO GALLEGOS RUIZ | C6: Aldo Gallegos Ruiz | D6: aldo.gallegos@arena-analytics.com | E6: Analítica | F6: Científico(a) de Datos Jr | G6: =_xlfn.XLOOKUP(H6,'Proyectos Dueños'!$B$2:$B$18,'Proyectos Dueños'!$C$2:$C$18,"") -> The Coca Cola Company | H6: OBPPC | I6: Luis Adrián Lara | K6: Share Forecast LATAM / Apollo 2.0 | L6: =_xlfn.XLOOKUP(K6,'Proyectos Dueños'!$B$2:$B$18,'Proyectos Dueños'!$D$2:$D$18,"") -> Oscar Andrés Mancha Mendoza | N6: =_xlfn.XLOOKUP(M6,'Proyectos Dueños'!$B$2:$B$18,'Proyectos Dueños'!$D$2:$D$18,"")
A7: 8 | B7: JESÚS ALEJANDRO OLIVARES PADILLA | C7: Alejandro Olivares Padilla | D7: alejandro.olivares@arena-analytics.com | E7: Analítica | F7: Ingeniero(a) de Datos Mid | G7: =_xlfn.XLOOKUP(H7,'Proyectos Dueños'!$B$2:$B$18,'Proyectos Dueños'!$C$2:$C$18,"") -> The Coca Cola Company | H7: MSI | I7: José Antonio Pedraza | L7: =_xlfn.XLOOKUP(K7,'Proyectos Dueños'!$B$2:$B$18,'Proyectos Dueños'!$D$2:$D$18,"") | N7: =_xlfn.XLOOKUP(M7,'Proyectos Dueños'!$B$2:$B$18,'Proyectos Dueños'!$D$2:$D$18,"")
A8: 10 | B8: ANDREA GUADALUPE PLASCENCIA RODRÍGUEZ | C8: Andrea Plascencia Rodríguez | D8: andrea.plascencia@arena-analytics.com | E8: Analítica | F8: Ingeniero(a) de Datos Jr | G8: =_xlfn.XLOOKUP(H8,'Proyectos Dueños'!$B$2:$B$18,'Proyectos Dueños'!$C$2:$C$18,"") -> The Coca Cola Company | H8: GenAI | I8: Marco Aristeo | L8: =_xlfn.XLOOKUP(K8,'Proyectos Dueños'!$B$2:$B$18,'Proyectos Dueños'!$D$2:$D$18,"") | N8: =_xlfn.XLOOKUP(M8,'Proyectos Dueños'!$B$2:$B$18,'Proyectos Dueños'!$D$2:$D$18,"")
A9: 11 | B9: JOSÉ ANTONIO PEDRAZA RANGEL | C9: Antonio Pedraza Rangel | D9: jose.pedraza@arena-analytics.com | E9: Analítica | F9: Product Manager Snr | G9: =_xlfn.XLOOKUP(H9,'Proyectos Dueños'!$B$2:$B$18,'Proyectos Dueños'!$C$2:$C$18,"") -> The Coca Cola Company | H9: MSI | I9: Héctor Rangel | L9: =_xlfn.XLOOKUP(K9,'Proyectos Dueños'!$B$2:$B$18,'Proyectos Dueños'!$D$2:$D$18,"") | N9: =_xlfn.XLOOKUP(M9,'Proyectos Dueños'!$B$2:$B$18,'Proyectos Dueños'!$D$2:$D$18,"")
A10: 13 | B10: CARLOS ALBERTO RUIZ ESTAÑÓN | C10: Carlos Alberto Ruiz Estañón | D10: carlos.ruiz@arena-analytics.com | E10: Analítica | F10: Ingeniero(a) de Datos Jr | G10: =_xlfn.XLOOKUP(H10,'Proyectos Dueños'!$B$2:$B$18,'Proyectos Dueños'!$C$2:$C$18,"") -> The Coca Cola Company | H10: Data Ops / MPM | I10: Kareem Galván | L10: =_xlfn.XLOOKUP(K10,'Proyectos Dueños'!$B$2:$B$18,'Proyectos Dueños'!$D$2:$D$18,"") | N10: =_xlfn.XLOOKUP(M10,'Proyectos Dueños'!$B$2:$B$18,'Proyectos Dueños'!$D$2:$D$18,"")
A11: 14 | B11: CARLOS ALFONSO BARRÓN RIVERA | C11: Carlos Alfonso Barrón Rivera | D11: alfonso.barron@arena-analytics.com | E11: Analítica | F11: Ingeniero(a) de Datos Jr | G11: =_xlfn.XLOOKUP(H11,'Proyectos Dueños'!$B$2:$B$18,'Proyectos Dueños'!$C$2:$C$18,"") -> The Coca Cola Company | H11: OBPPC | I11: Luis Adrián Lara | L11: =_xlfn.XLOOKUP(K11,'Proyectos Dueños'!$B$2:$B$18,'Proyectos Dueños'!$D$2:$D$18,"") | N11: =_xlfn.XLOOKUP(M11,'Proyectos Dueños'!$B$2:$B$18,'Proyectos Dueños'!$D$2:$D$18,"")
A12: 20 | B12: DANTE OCTAVIO GODINEZ ALDANA | C12: Dante Godinez Aldana | D12: dante.godinez@arena-analytics.com | E12: Analítica | F12: UX / UI | G12: =_xlfn.XLOOKUP(H12,'Proyectos Dueños'!$B$2:$B$18,'Proyectos Dueños'!$C$2:$C$18,"") -> Coppel | H12: Coppel Portal (Sistema de Gestión de Categorías) | I12: Carolina Palacio | L12: =_xlfn.XLOOKUP(K12,'Proyectos Dueños'!$B$2:$B$18,'Proyectos Dueños'!$D$2:$D$18,"") | N12: =_xlfn.XLOOKUP(M12,'Proyectos Dueños'!$B$2:$B$18,'Proyectos Dueños'!$D$2:$D$18,"")
A13: 21 | B13: DAVID PASTOR MARTÍNEZ ULLOA | C13: David Pastor Martínez Ulloa | D13: dpastor@arena-analytics.com | E13: Analítica | F13: Ingeniero(a) de Datos Mid | G13: =_xlfn.XLOOKUP(H13,'Proyectos Dueños'!$B$2:$B$18,'Proyectos Dueños'!$C$2:$C$18,"") -> The Coca Cola Company | H13: GenAI | I13: Marco Aristeo | L13: =_xlfn.XLOOKUP(K13,'Proyectos Dueños'!$B$2:$B$18,'Proyectos Dueños'!$D$2:$D$18,"") | N13: =_xlfn.XLOOKUP(M13,'Proyectos Dueños'!$B$2:$B$18,'Proyectos Dueños'!$D$2:$D$18,"")
A14: 22 | B14: DIANA ITZEL VAZQUEZ SANTIAGO | C14: Diana Vazquez Santiago | D14: divazquez@arena-analytics.com | E14: Analítica | F14: Científico(a) de Datos Mid | G14: =_xlfn.XLOOKUP(H14,'Proyectos Dueños'!$B$2:$B$18,'Proyectos Dueños'!$C$2:$C$18,"") -> The Coca Cola Company | H14: Share Forecast LATAM / Apollo 2.0 | I14: Oscar Mancha | L14: =_xlfn.XLOOKUP(K14,'Proyectos Dueños'!$B$2:$B$18,'Proyectos Dueños'!$D$2:$D$18,"") | N14: =_xlfn.XLOOKUP(M14,'Proyectos Dueños'!$B$2:$B$18,'Proyectos Dueños'!$D$2:$D$18,"")
A15: 23 | B15: EDUARDO ALAIN ESPINOZA DE LA CRUZ | C15: Eduardo Alain Espinoza De La Cruz | D15: eduardo.espinoza@arena-analytics.com | E15: Analítica | F15: Ingeniero(a) de Datos Jr | G15: =_xlfn.XLOOKUP(H15,'Proyectos Dueños'!$B$2:$B$18,'Proyectos Dueños'!$C$2:$C$18,"") -> The Coca Cola Company | H15: Share Forecast LATAM / Apollo 2.0 | I15: Oscar Mancha | L15: =_xlfn.XLOOKUP(K15,'Proyectos Dueños'!$B$2:$B$18,'Proyectos Dueños'!$D$2:$D$18,"") | N15: =_xlfn.XLOOKUP(M15,'Proyectos Dueños'!$B$2:$B$18,'Proyectos Dueños'!$D$2:$D$18,"")
A16: 24 | B16: RAUL EDUARDO AYALA SOTO | C16: Eduardo Ayala | D16: eduardo.ayala@arena-analytics.com | E16: Analítica | F16: Product Manager Snr | G16: =_xlfn.XLOOKUP(H16,'Proyectos Dueños'!$B$2:$B$18,'Proyectos Dueños'!$C$2:$C$18,"") -> The Coca Cola Company | H16: NSR PM & Comm | I16: Héctor Rangel | K16: Weather | L16: =_xlfn.XLOOKUP(K16,'Proyectos Dueños'!$B$2:$B$18,'Proyectos Dueños'!$D$2:$D$18,"") -> Eduardo Ayala | N16: =_xlfn.XLOOKUP(M16,'Proyectos Dueños'!$B$2:$B$18,'Proyectos Dueños'!$D$2:$D$18,"")
A17: 25 | B17: EDWARD IGNACIO GÓMEZ RUIZ | C17: Edward Gómez Ruiz | D17: edward.gomez@arena-analytics.com | E17: Analítica | F17: Product Manager Mid | G17: =_xlfn.XLOOKUP(H17,'Proyectos Dueños'!$B$2:$B$18,'Proyectos Dueños'!$C$2:$C$18,"") -> The Coca Cola Company | H17: Share Forecast LATAM / Apollo 2.0 | I17: Oscar Mancha | L17: =_xlfn.XLOOKUP(K17,'Proyectos Dueños'!$B$2:$B$18,'Proyectos Dueños'!$D$2:$D$18,"") | N17: =_xlfn.XLOOKUP(M17,'Proyectos Dueños'!$B$2:$B$18,'Proyectos Dueños'!$D$2:$D$18,"")
A18: 26 | B18: ELÍAS ABRAHAM GARCÍA MENDOZA | C18: Elías García Mendoza | D18: elias.garcia@arena-analytics.com | E18: Analítica | F18: Ingeniero(a) de Datos Jr | G18: =_xlfn.XLOOKUP(H18,'Proyectos Dueños'!$B$2:$B$18,'Proyectos Dueños'!$C$2:$C$18,"") -> The Coca Cola Company | H18: C&CL Report | I18: José Antonio Pedraza | K18: CCL Engineering Cell | L18: =_xlfn.XLOOKUP(K18,'Proyectos Dueños'!$B$2:$B$18,'Proyectos Dueños'!$D$2:$D$18,"") -> Héctor Rangel Castro | M18: Weather | N18: =_xlfn.XLOOKUP(M18,'Proyectos Dueños'!$B$2:$B$18,'Proyectos Dueños'!$D$2:$D$18,"") -> Eduardo Ayala
A19: 27 | B19: EMILIO OLMOS SÁNCHEZ | C19: Emilio Olmos Sánchez | D19: emilio.olmos@arena-analytics.com | E19: Analítica | F19: Product Manager Jr | G19: =_xlfn.XLOOKUP(H19,'Proyectos Dueños'!$B$2:$B$18,'Proyectos Dueños'!$C$2:$C$18,"") -> The Coca Cola Company | H19: MSI | I19: José Antonio Pedraza | L19: =_xlfn.XLOOKUP(K19,'Proyectos Dueños'!$B$2:$B$18,'Proyectos Dueños'!$D$2:$D$18,"") | N19: =_xlfn.XLOOKUP(M19,'Proyectos Dueños'!$B$2:$B$18,'Proyectos Dueños'!$D$2:$D$18,"")
A20: 28 | B20: ERICK LÓPEZ CRUZ | C20: Erick López Cruz | D20: erick.lopez@arena-analytics.com | E20: Analítica | F20: Ingeniero(a) de Datos Jr | G20: =_xlfn.XLOOKUP(H20,'Proyectos Dueños'!$B$2:$B$18,'Proyectos Dueños'!$C$2:$C$18,"") -> The Coca Cola Company | H20: Migración 360 a 720 | I20: Kareem Galván | K20: NSR PM & Comm | L20: =_xlfn.XLOOKUP(K20,'Proyectos Dueños'!$B$2:$B$18,'Proyectos Dueños'!$D$2:$D$18,"") -> Eduardo Ayala | N20: =_xlfn.XLOOKUP(M20,'Proyectos Dueños'!$B$2:$B$18,'Proyectos Dueños'!$D$2:$D$18,"")
A21: 29 | B21: FEDERICO LAGOS GUIZAR | C21: Federico Lagos | D21: flagos@arena-analytics.com | E21: Analítica | F21: Ingeniero(a) de Datos Snr | G21: =_xlfn.XLOOKUP(H21,'Proyectos Dueños'!$B$2:$B$18,'Proyectos Dueños'!$C$2:$C$18,"") -> The Coca Cola Company | H21: MSI | I21: José Antonio Pedraza | L21: =_xlfn.XLOOKUP(K21,'Proyectos Dueños'!$B$2:$B$18,'Proyectos Dueños'!$D$2:$D$18,"") | N21: =_xlfn.XLOOKUP(M21,'Proyectos Dueños'!$B$2:$B$18,'Proyectos Dueños'!$D$2:$D$18,"")
A22: 30 | B22: FELIPE DE JESÚS ZETINA SALGADO | C22: Felipe Zetina Salgado | D22: felipe.zetina@arena-analytics.com | E22: Analítica | F22: Ingeniero(a) de Datos Jr | G22: =_xlfn.XLOOKUP(H22,'Proyectos Dueños'!$B$2:$B$18,'Proyectos Dueños'!$C$2:$C$18,"") -> The Coca Cola Company | H22: MSI | I22: José Antonio Pedraza | L22: =_xlfn.XLOOKUP(K22,'Proyectos Dueños'!$B$2:$B$18,'Proyectos Dueños'!$D$2:$D$18,"") | N22: =_xlfn.XLOOKUP(M22,'Proyectos Dueños'!$B$2:$B$18,'Proyectos Dueños'!$D$2:$D$18,"")
A23: 33 | B23: FRANCISCO MANUEL BARRIOS PANIAGUA | C23: Francisco Barrios Paniagua | D23: fbarrios@arena-analytics.com | E23: Analítica | F23: Científico(a) de Datos Lead | G23: =_xlfn.XLOOKUP(H23,'Proyectos Dueños'!$B$2:$B$18,'Proyectos Dueños'!$C$2:$C$18,"") | I23: Héctor Rangel
A24: 35 | B24: ERIKA GABRIELA TOSTADO MILLAN | C24: Gabriela Tostado | D24: gabriela.tostado@arena-analytics.com | E24: Analítica | F24: UX / UI | G24: =_xlfn.XLOOKUP(H24,'Proyectos Dueños'!$B$2:$B$18,'Proyectos Dueños'!$C$2:$C$18,"") -> Coppel | H24: Coppel Portal (Sistema de Gestión de Categorías) | I24: Carolina Palacio | L24: =_xlfn.XLOOKUP(K24,'Proyectos Dueños'!$B$2:$B$18,'Proyectos Dueños'!$D$2:$D$18,"") | N24: =_xlfn.XLOOKUP(M24,'Proyectos Dueños'!$B$2:$B$18,'Proyectos Dueños'!$D$2:$D$18,"")
A25: 36 | B25: JOSE GERARDO ESPINOZA JIMENEZ | C25: Gerardo Espinoza Jimenez | D25: gerardo@arena-analytics.com | E25: Analítica | F25: Product Manager Mid | G25: =_xlfn.XLOOKUP(H25,'Proyectos Dueños'!$B$2:$B$18,'Proyectos Dueños'!$C$2:$C$18,"") -> The Coca Cola Company | H25: MSI | I25: José Antonio Pedraza | L25: =_xlfn.XLOOKUP(K25,'Proyectos Dueños'!$B$2:$B$18,'Proyectos Dueños'!$D$2:$D$18,"") | N25: =_xlfn.XLOOKUP(M25,'Proyectos Dueños'!$B$2:$B$18,'Proyectos Dueños'!$D$2:$D$18,"")
A26: 40 | B26: ILSE HERNÁNDEZ MINUTTI | C26: Ilse Hernández Minutti | D26: ilse.hernandez@arena-analytics.com | E26: Analítica | F26: Ingeniero(a) de Datos Jr | G26: =_xlfn.XLOOKUP(H26,'Proyectos Dueños'!$B$2:$B$18,'Proyectos Dueños'!$C$2:$C$18,"") -> The Coca Cola Company | H26: CCL Engineering Cell | I26: Héctor Rangel | K26: Prime Partners Support | L26: =_xlfn.XLOOKUP(K26,'Proyectos Dueños'!$B$2:$B$18,'Proyectos Dueños'!$D$2:$D$18,"") -> Marco Aristeo García | N26: =_xlfn.XLOOKUP(M26,'Proyectos Dueños'!$B$2:$B$18,'Proyectos Dueños'!$D$2:$D$18,"")
A27: 41 | B27: IÑAKI FERNÁNDEZ FISCAL | C27: Iñaki Fernández Fiscal | D27: inaki.fernandez@arena-analytics.com | E27: Analítica | F27: Product Manager Jr | G27: =_xlfn.XLOOKUP(H27,'Proyectos Dueños'!$B$2:$B$18,'Proyectos Dueños'!$C$2:$C$18,"") -> The Coca Cola Company | H27: GenAI | I27: Marco Aristeo | L27: =_xlfn.XLOOKUP(K27,'Proyectos Dueños'!$B$2:$B$18,'Proyectos Dueños'!$D$2:$D$18,"") | N27: =_xlfn.XLOOKUP(M27,'Proyectos Dueños'!$B$2:$B$18,'Proyectos Dueños'!$D$2:$D$18,"")
A28: 43 | B28: JAVIER MARTÍNEZ CARRANZA | C28: Javier Martínez Carranza | D28: javier.martinez@arena-analytics.com | E28: Analítica | F28: Ingeniero(a) de Datos Jr | G28: =_xlfn.XLOOKUP(H28,'Proyectos Dueños'!$B$2:$B$18,'Proyectos Dueños'!$C$2:$C$18,"") -> The Coca Cola Company | H28: Share Forecast LATAM / Apollo 2.0 | I28: Oscar Mancha | L28: =_xlfn.XLOOKUP(K28,'Proyectos Dueños'!$B$2:$B$18,'Proyectos Dueños'!$D$2:$D$18,"") | N28: =_xlfn.XLOOKUP(M28,'Proyectos Dueños'!$B$2:$B$18,'Proyectos Dueños'!$D$2:$D$18,"")
A29: 45 | B29: JORGE ANTONIO VARGAS RAMOS | C29: Jorge Vargas Ramos | D29: jorge.vargas@arena-analytics.com | E29: Analítica | F29: UX / UI | G29: =_xlfn.XLOOKUP(H29,'Proyectos Dueños'!$B$2:$B$18,'Proyectos Dueños'!$C$2:$C$18,"") -> Coppel | H29: Coppel Portal (Sistema de Gestión de Categorías) | I29: Carolina Palacio | K29: GenAI | L29: =_xlfn.XLOOKUP(K29,'Proyectos Dueños'!$B$2:$B$18,'Proyectos Dueños'!$D$2:$D$18,"") -> Iñaki Fernandez | M29: OBPPC | N29: =_xlfn.XLOOKUP(M29,'Proyectos Dueños'!$B$2:$B$18,'Proyectos Dueños'!$D$2:$D$18,"") -> Luis Adrián Lara García
A30: 46 | B30: JOSE ROBLES NORIEGA | C30: Jose Robles Noriega | D30: jrobles@arena-analytics.com | E30: Analítica | F30: Científico(a) de Datos Snr | G30: =_xlfn.XLOOKUP(H30,'Proyectos Dueños'!$B$2:$B$18,'Proyectos Dueños'!$C$2:$C$18,"") -> The Coca Cola Company | H30: OBPPC | I30: Luis Adrián Lara | L30: =_xlfn.XLOOKUP(K30,'Proyectos Dueños'!$B$2:$B$18,'Proyectos Dueños'!$D$2:$D$18,"") | N30: =_xlfn.XLOOKUP(M30,'Proyectos Dueños'!$B$2:$B$18,'Proyectos Dueños'!$D$2:$D$18,"")
A31: 49 | B31: JUAN DANIEL GRANADOS ROMO | C31: Juan Daniel Granados | D31: juan.granados@arena-analytics.com | E31: Analítica | F31: Ingeniero(a) de Datos Jr | G31: =_xlfn.XLOOKUP(H31,'Proyectos Dueños'!$B$2:$B$18,'Proyectos Dueños'!$C$2:$C$18,"") -> The Coca Cola Company | H31: MSI | I31: José Antonio Pedraza | L31: =_xlfn.XLOOKUP(K31,'Proyectos Dueños'!$B$2:$B$18,'Proyectos Dueños'!$D$2:$D$18,"") | N31: =_xlfn.XLOOKUP(M31,'Proyectos Dueños'!$B$2:$B$18,'Proyectos Dueños'!$D$2:$D$18,"")
A32: 50 | B32: JUAN LUIS VELÁZQUEZ MORALES | C32: Juan Luis Velázquez Morales | D32: juan.velazquez@arena-analytics.com | E32: Analítica | F32: Ingeniero(a) de Datos Jr | G32: =_xlfn.XLOOKUP(H32,'Proyectos Dueños'!$B$2:$B$18,'Proyectos Dueños'!$C$2:$C$18,"") -> The Coca Cola Company | H32: Data Ops / MPM | I32: Kareem Galván | L32: =_xlfn.XLOOKUP(K32,'Proyectos Dueños'!$B$2:$B$18,'Proyectos Dueños'!$D$2:$D$18,"") | N32: =_xlfn.XLOOKUP(M32,'Proyectos Dueños'!$B$2:$B$18,'Proyectos Dueños'!$D$2:$D$18,"")
A33: 51 | B33: JUAN PABLO MONTOYA GUZMÁN | C33: Juan Pablo Montoya Guzmán | D33: juan.montoya@arena-analytics.com | E33: Analítica | F33: Product Manager Mid | G33: =_xlfn.XLOOKUP(H33,'Proyectos Dueños'!$B$2:$B$18,'Proyectos Dueños'!$C$2:$C$18,"") -> The Coca Cola Company | H33: Data Ops / MPM | I33: Kareem Galván | L33: =_xlfn.XLOOKUP(K33,'Proyectos Dueños'!$B$2:$B$18,'Proyectos Dueños'!$D$2:$D$18,"") | N33: =_xlfn.XLOOKUP(M33,'Proyectos Dueños'!$B$2:$B$18,'Proyectos Dueños'!$D$2:$D$18,"")
A34: 52 | B34: KAREEM GALVÁN DELGADILLO | C34: Kareem Galván | D34: kareem.galvan@arena-analytics.com | E34: Analítica | F34: Product Manager Mid | G34: =_xlfn.XLOOKUP(H34,'Proyectos Dueños'!$B$2:$B$18,'Proyectos Dueños'!$C$2:$C$18,"") -> The Coca Cola Company | H34: Data Ops / MPM | I34: Kareem Galván | K34: Hypercare Migración 360 a 720 | L34: =_xlfn.XLOOKUP(K34,'Proyectos Dueños'!$B$2:$B$18,'Proyectos Dueños'!$D$2:$D$18,"") -> Kareem Galván | M34: Migración 360 a 720 | N34: =_xlfn.XLOOKUP(M34,'Proyectos Dueños'!$B$2:$B$18,'Proyectos Dueños'!$D$2:$D$18,"") -> Kareem Galvan
A35: 54 | B35: LORENA MONSERRAT CAMPUZANO SÁNCHEZ | C35: Lorena Campuzano Sánchez | D35: lorena.campuzano@arena-analytics.com | E35: Analítica | F35: Ingeniero(a) de Datos Jr | G35: =_xlfn.XLOOKUP(H35,'Proyectos Dueños'!$B$2:$B$18,'Proyectos Dueños'!$C$2:$C$18,"") -> The Coca Cola Company | H35: Weather | I35: Eduardo Ayala | L35: =_xlfn.XLOOKUP(K35,'Proyectos Dueños'!$B$2:$B$18,'Proyectos Dueños'!$D$2:$D$18,"") | N35: =_xlfn.XLOOKUP(M35,'Proyectos Dueños'!$B$2:$B$18,'Proyectos Dueños'!$D$2:$D$18,"")
A36: 55 | B36: LORENZO LLAGUNO | C36: Lorenzo Llaguno | D36: lorenzo@arena-analytics.com | E36: Analítica | F36: Product Manager Jr | G36: =_xlfn.XLOOKUP(H36,'Proyectos Dueños'!$B$2:$B$18,'Proyectos Dueños'!$C$2:$C$18,"") -> The Coca Cola Company | H36: AI Latam Office Program Manager | I36: Lorenzo Llaguno | K36: NSR PM & Comm | L36: =_xlfn.XLOOKUP(K36,'Proyectos Dueños'!$B$2:$B$18,'Proyectos Dueños'!$D$2:$D$18,"") -> Eduardo Ayala | N36: =_xlfn.XLOOKUP(M36,'Proyectos Dueños'!$B$2:$B$18,'Proyectos Dueños'!$D$2:$D$18,"")
A37: 56 | B37: LOURDES MARTINEZ MARTINEZ | C37: Lourdes Martínez Martínez | D37: lourdes.martinez@arena-analytics.com | E37: Analítica | F37: Ingeniero(a) de Datos Jr | G37: =_xlfn.XLOOKUP(H37,'Proyectos Dueños'!$B$2:$B$18,'Proyectos Dueños'!$C$2:$C$18,"") -> The Coca Cola Company | H37: Data Ops / MPM | I37: Kareem Galván | L37: =_xlfn.XLOOKUP(K37,'Proyectos Dueños'!$B$2:$B$18,'Proyectos Dueños'!$D$2:$D$18,"") | N37: =_xlfn.XLOOKUP(M37,'Proyectos Dueños'!$B$2:$B$18,'Proyectos Dueños'!$D$2:$D$18,"")
A38: 57 | B38: LUIS ADRIÁN LARA GARCÍA | C38: Luis Adrián Lara García | D38: luis.lara@arena-analytics.com | E38: Analítica | F38: Product Manager Snr | G38: =_xlfn.XLOOKUP(H38,'Proyectos Dueños'!$B$2:$B$18,'Proyectos Dueños'!$C$2:$C$18,"") -> The Coca Cola Company | H38: OBPPC | I38: Héctor Rangel | L38: =_xlfn.XLOOKUP(K38,'Proyectos Dueños'!$B$2:$B$18,'Proyectos Dueños'!$D$2:$D$18,"") | N38: =_xlfn.XLOOKUP(M38,'Proyectos Dueños'!$B$2:$B$18,'Proyectos Dueños'!$D$2:$D$18,"")
A39: 58 | B39: LUIS ANTONIO FLORES CASTRO | C39: Luis Antonio Flores Castro | D39: luis.flores@arena-analytics.com | E39: Analítica | F39: Ingeniero(a) de Datos Jr | G39: =_xlfn.XLOOKUP(H39,'Proyectos Dueños'!$B$2:$B$18,'Proyectos Dueños'!$C$2:$C$18,"") -> The Coca Cola Company | H39: Data Ops / MPM | I39: Kareem Galván | L39: =_xlfn.XLOOKUP(K39,'Proyectos Dueños'!$B$2:$B$18,'Proyectos Dueños'!$D$2:$D$18,"") | N39: =_xlfn.XLOOKUP(M39,'Proyectos Dueños'!$B$2:$B$18,'Proyectos Dueños'!$D$2:$D$18,"")
A40: 59 | B40: LUIS JESUS BECERRIL VILLASEÑOR | C40: Luis Becerril Villaseñor | D40: luis@arena-analytics.com | E40: Analítica | F40: Product Manager Lead | G40: =_xlfn.XLOOKUP(H40,'Proyectos Dueños'!$B$2:$B$18,'Proyectos Dueños'!$C$2:$C$18,"") | I40: Héctor Rangel
...

Sheet Proyectos
A1: Employee | B1: Project | C1: Min of Start | D1: Max of End
A2: Abad Arellano Cardona | B2: CCL Engineering Cell | C2: 46125 | D2: 46402
A3: Abad Arellano Cardona | B3: Migración 360 a 720 | C3: 46104 | D3: 46199
A4: Abad Arellano Cardona | B4: OBPPC | C4: 45727 | D4: 46387
A5: Abad Arellano Cardona | B5: Prime Partners Support | C5: 45978 | D5: 46122
A6: Abad Arellano Cardona | B6: Rodin | C6: 46055 | D6: 46416
A7: Abad Arellano Cardona | B7: Weather | C7: 46042 | D7: 46178
A8: Abraham Martínez Ramirez | B8: C&CL Report | C8: 46058 | D8: 46122
A9: Abraham Martínez Ramirez | B9: Dashboard Comercial Cono Sur | C9: 46090 | D9: 46108
A10: Abraham Martínez Ramirez | B10: OBPPC | C10: 46034 | D10: 46373
A11: Abraham Martínez Ramirez | B11: Share Forecast LATAM / Apollo 2.0 | C11: 46118 | D11: 46387
A12: Adrián Landaverde Nava | B12: GenAI | C12: 46098 | D12: 46203
A13: Adrián Landaverde Nava | B13: Weather | C13: 46042 | D13: 46094
... A100: Mario De Gyves Pulido | B100: MSI | C100: 46023 | D100: 46295
B101: OBPPC | C101: 46034 | D101: 46373
B102: Share Forecast LATAM / Apollo 2.0 | C102: 46023 | D102: 46387
A103: Héctor Rangel Castro | B103: AI Latam Office Program Manager | C103: 46118 | D103: 46386
B104: C&CL Report | C104: 46058 | D104: 46122
B105: CCL Engineering Cell | C105: 46125 | D105: 46402
B106: Dashboard Comercial Cono Sur | C106: 46090 | D106: 46108
B107: GenAI | C107: 46069 | D107: 46203
B108: Hypercare Migración 360 a 720 | C108: 46195 | D108: 46283
B109: Migración 360 a 720 | C109: 46104 | D109: 46199
B110: Prime Partners Support | C110: 45978 | D110: 46122
B111: Urrea Bolsa de Horas | C111: 46118 | D111: 46206
B112: Weather | C112: 46042 | D112: 46178
A113: Oscar Germán Nafarrate Salum | B113: Business Terms Harmonization & SSOT | C113: 46090 | D113: 46178
B114: Data Ops / MPM | C114: 45811 | D114: 46783

Sheet Proyectos Dueños
A1: ID | B1: Nombre | C1: Cliente | D1: Owner | E1: Responsable | F1: Kick-off | G1: Target Cierre | H1: Status | I1: Descripción
A2: P14 | B2: MSI | C2: The Coca Cola Company | D2: José Antonio Pedraza Rangel | E2: Mario De Gyves | F2: 2026-01-01 | G2: 2026-09-30 | H2: Delayed
A3: P12 | B3: Share Forecast LATAM / Apollo 2.0 | C3: The Coca Cola Company | D3: Oscar Andrés Mancha Mendoza | E3: Mario De Gyves | F3: 2026-01-01 | G3: 2026-12-31 | H3: On track
A4: P4 | B4: Data Ops / MPM | C4: The Coca Cola Company | D4: Kareem Galván Delgadillo | E4: Oscar Nafarrate | F4: 2025-06-03 | G4: 2028-01-31 | H4: On track
A5: P9 | B5: GenAI | C5: The Coca Cola Company | D5: Iñaki Fernandez | E5: Héctor Rangel Castro | F5: 2026-02-16 | G5: 2026-06-30 | H5: On track
A6: P21 | B6: AI Latam Office Program Manager | C6: The Coca Cola Company | D6: Lorenzo Llaguno | E6: Héctor Rangel Castro | F6: 2026-04-06 | G6: 2026-12-30 | H6: On track
A7: P13 | B7: OBPPC | C7: The Coca Cola Company | D7: Luis Adrián Lara García | E7: Mario De Gyves | F7: 2025-03-11 | G7: 2026-12-31 | H7: On track
A8: P8 | B8: Weather | C8: The Coca Cola Company | D8: Eduardo Ayala | E8: Luis Becerril | F8: 2026-01-20 | G8: 2026-06-05 | H8: On track
A9: P18 | B9: Migración 360 a 720 | C9: The Coca Cola Company | D9: Kareem Galvan | E9: Héctor Rangel Castro | F9: 2026-03-23 | G9: 2026-06-12 | H9: On track
A10: P22 | B10: CCL Engineering Cell | C10: The Coca Cola Company | D10: Héctor Rangel Castro | E10: Marco Aristeo Garcia | F10: 2026-04-13 | G10: 2027-01-15 | H10: On track
A11: P19 | B11: Hypercare Migración 360 a 720 | C11: The Coca Cola Company | D11: Kareem Galván | E11: Héctor Rangel Castro | F11: 2026-06-22 | G11: 2026-09-18 | H11: On track
A12: P15 | B12: Business Terms Harmonization & SSOT | C12: Cuervo | D12: Carlos Alejandro Rodríguez Ochoa | E12: Oscar Nafarrate | F12: 2026-03-09 | G12: 2026-05-22 | H12: On track
A13: P5 | B13: Rodin | C13: Rodin | D13: Emanuel Alvarado | E13: Luis Becerril | F13: 2026-02-01 | G13: 2027-01-31 | H13: On track
... A18: P10 | B18: C&CL Report | C18: The Coca Cola Company | D18: José Antonio Pedraza Rangel | E18: Héctor Rangel | F18: 2026-02-05 | G18: 2026-02-05 | H18: On track
